Workbook

Sheet Healthcare Insurance
A1: Name | B1: Age | C1: Gender | D1: BMI | E1: Children | F1: Smoking Status | G1: Location | H1: Insurance Price (USD) | I1: Age Group | J1: BMI | K1: Risk Segmentation | L1: High Risk Customer
A2: John Smith | B2: 35 | C2: Male | D2: 29.5 | E2: 0 | F2: Non-Smoker | G2: New York | H2: 16450 | I2: =IF(B2<30,"Under30",IF(B2<=45,"30-45","Above 45")) -> 30-45 | J2: =IF(D2<18.5,"Under Weight",IF(D2<25,"Normal",IF(D2<30,"Overweight","Obese"))) -> Overweight | K2: =IF(H2<16000,"Low",IF(H2<25000,"Medium","High")) -> Medium | L2: =IF(AND(B2>40,D2>30,F2="Smoker"),"High Risk","Normal") -> Normal
A3: Emily Johnson | B3: 42 | C3: Female | D3: 26.8 | E3: 2 | F3: Non-Smoker | G3: Los Angeles | H3: 21600 | I3: =IF(B3<30,"Under30",IF(B3<=45,"30-45","Above 45")) -> 30-45 | J3: =IF(D3<18.5,"Under Weight",IF(D3<25,"Normal",IF(D3<30,"Overweight","Obese"))) -> Overweight | K3: =IF(H3<16000,"Low",IF(H3<25000,"Medium","High")) -> Medium | L3: =IF(AND(B3>40,D3>30,F3="Smoker"),"High Risk","Normal") -> Normal
A4: Michael Williams | B4: 50 | C4: Male | D4: 31.2 | E4: 3 | F4: Smoker | G4: Chicago | H4: 21080 | I4: =IF(B4<30,"Under30",IF(B4<=45,"30-45","Above 45")) -> Above 45 | J4: =IF(D4<18.5,"Under Weight",IF(D4<25,"Normal",IF(D4<30,"Overweight","Obese"))) -> Obese | K4: =IF(H4<16000,"Low",IF(H4<25000,"Medium","High")) -> Medium | L4: =IF(AND(B4>40,D4>30,F4="Smoker"),"High Risk","Normal") -> High Risk
A5: Sarah Brown | B5: 28 | C5: Female | D5: 22.3 | E5: 1 | F5: Non-Smoker | G5: Houston | H5: 10080 | I5: =IF(B5<30,"Under30",IF(B5<=45,"30-45","Above 45")) -> Under30 | J5: =IF(D5<18.5,"Under Weight",IF(D5<25,"Normal",IF(D5<30,"Overweight","Obese"))) -> Normal | K5: =IF(H5<16000,"Low",IF(H5<25000,"Medium","High")) -> Low | L5: =IF(AND(B5>40,D5>30,F5="Smoker"),"High Risk","Normal") -> Normal
A6: David Jones | B6: 39 | C6: Male | D6: 28.1 | E6: 2 | F6: Non-Smoker | G6: Phoenix | H6: 17640 | I6: =IF(B6<30,"Under30",IF(B6<=45,"30-45","Above 45")) -> 30-45 | J6: =IF(D6<18.5,"Under Weight",IF(D6<25,"Normal",IF(D6<30,"Overweight","Obese"))) -> Overweight | K6: =IF(H6<16000,"Low",IF(H6<25000,"Medium","High")) -> Medium | L6: =IF(AND(B6>40,D6>30,F6="Smoker"),"High Risk","Normal") -> Normal
A7: Jennifer Martinez | B7: 45 | C7: Female | D7: 29.9 | E7: 0 | F7: Non-Smoker | G7: Philadelphia | H7: 18000 | I7: =IF(B7<30,"Under30",IF(B7<=45,"30-45","Above 45")) -> 30-45 | J7: =IF(D7<18.5,"Under Weight",IF(D7<25,"Normal",IF(D7<30,"Overweight","Obese"))) -> Overweight | K7: =IF(H7<16000,"Low",IF(H7<25000,"Medium","High")) -> Medium | L7: =IF(AND(B7>40,D7>30,F7="Smoker"),"High Risk","Normal") -> Normal
A8: Daniel Anderson | B8: 33 | C8: Male | D8: 25.5 | E8: 1 | F8: Non-Smoker | G8: San Antonio | H8: 11520 | I8: =IF(B8<30,"Under30",IF(B8<=45,"30-45","Above 45")) -> 30-45 | J8: =IF(D8<18.5,"Under Weight",IF(D8<25,"Normal",IF(D8<30,"Overweight","Obese"))) -> Overweight | K8: =IF(H8<16000,"Low",IF(H8<25000,"Medium","High")) -> Low | L8: =IF(AND(B8>40,D8>30,F8="Smoker"),"High Risk","Normal") -> Normal
A9: Jessica Wilson | B9: 37 | C9: Female | D9: 27.4 | E9: 2 | F9: Smoker | G9: San Diego | H9: 16120 | I9: =IF(B9<30,"Under30",IF(B9<=45,"30-45","Above 45")) -> 30-45 | J9: =IF(D9<18.5,"Under Weight",IF(D9<25,"Normal",IF(D9<30,"Overweight","Obese"))) -> Overweight | K9: =IF(H9<16000,"Low",IF(H9<25000,"Medium","High")) -> Medium | L9: =IF(AND(B9>40,D9>30,F9="Smoker"),"High Risk","Normal") -> Normal
A10: Matthew Taylor | B10: 47 | C10: Male | D10: 33 | E10: 3 | F10: Non-Smoker | G10: Dallas | H10: 19720 | I10: =IF(B10<30,"Under30",IF(B10<=45,"30-45","Above 45")) -> Above 45 | J10: =IF(D10<18.5,"Under Weight",IF(D10<25,"Normal",IF(D10<30,"Overweight","Obese"))) -> Obese | K10: =IF(H10<16000,"Low",IF(H10<25000,"Medium","High")) -> Medium | L10: =IF(AND(B10>40,D10>30,F10="Smoker"),"High Risk","Normal") -> Normal
A11: Emma Garcia | B11: 31 | C11: Female | D11: 24.7 | E11: 0 | F11: Non-Smoker | G11: San Jose | H11: 11100 | I11: =IF(B11<30,"Under30",IF(B11<=45,"30-45","Above 45")) -> 30-45 | J11: =IF(D11<18.5,"Under Weight",IF(D11<25,"Normal",IF(D11<30,"Overweight","Obese"))) -> Normal | K11: =IF(H11<16000,"Low",IF(H11<25000,"Medium","High")) -> Low | L11: =IF(AND(B11>40,D11>30,F11="Smoker"),"High Risk","Normal") -> Normal
A12: Christopher Rodriguez | B12: 40 | C12: Male | D12: 30.5 | E12: 2 | F12: Non-Smoker | G12: Austin | H12: 18920 | I12: =IF(B12<30,"Under30",IF(B12<=45,"30-45","Above 45")) -> 30-45 | J12: =IF(D12<18.5,"Under Weight",IF(D12<25,"Normal",IF(D12<30,"Overweight","Obese"))) -> Obese | K12: =IF(H12<16000,"Low",IF(H12<25000,"Medium","High")) -> Medium | L12: =IF(AND(B12>40,D12>30,F12="Smoker"),"High Risk","Normal") -> Normal
A13: Olivia Hernandez | B13: 29 | C13: Female | D13: 23.9 | E13: 1 | F13: Non-Smoker | G13: Jacksonville | H13: 11020 | I13: =IF(B13<30,"Under30",IF(B13<=45,"30-45","Above 45")) -> Under30 | J13: =IF(D13<18.5,"Under Weight",IF(D13<25,"Normal",IF(D13<30,"Overweight","Obese"))) -> Normal | K13: =IF(H13<16000,"Low",IF(H13<25000,"Medium","High")) -> Low | L13: =IF(AND(B13>40,D13>30,F13="Smoker"),"High Risk","Normal") -> Normal
... A47: Sophia Foster | B47: 30 | C47: Female | D47: 25.8 | E47: 0 | F47: Non-Smoker | G47: New Orleans | H47: 11840 | I47: =IF(B47<30,"Under30",IF(B47<=45,"30-45","Above 45")) -> 30-45 | J47: =IF(D47<18.5,"Under Weight",IF(D47<25,"Normal",IF(D47<30,"Overweight","Obese"))) -> Overweight | K47: =IF(H47<16000,"Low",IF(H47<25000,"Medium","High")) -> Low | L47: =IF(AND(B47>40,D47>30,F47="Smoker"),"High Risk","Normal") -> Normal

Sheet Stakholder Prlm
B2: How many total customers are there in the dataset?
D3: =COUNTA('Healthcare Insurance'!A2:A47) -> 46
B5: What is the average insurance price (USD) across all customers?
D6: =AVERAGE('Healthcare Insurance'!H2:H47) -> 18244.348
B8: What is the minimum and maximum insurance price?
C9: Min | D9: Max
C10: =MIN('Healthcare Insurance'!H2:H47) -> 9600 | D10: =MAX('Healthcare Insurance'!H2:H47) -> 32120
B12: How many male vs female customers are there?
C13: Male | D13: Female
C14: =COUNTIF('Healthcare Insurance'!C2:C47,"Male") -> 23 | D14: =COUNTIF('Healthcare Insurance'!C2:C47,"Female") -> 23
B16: What is the average age of customers?
D17: =AVERAGE('Healthcare Insurance'!B2:B47) -> 39.695652
B19: What is the average BMI of customers?
D20: =AVERAGE('Healthcare Insurance'!D2:D47) -> 29.104348
B22: How many customers are smokers vs non-smokers?
C23: Smokers | D23: Non-Smokers
C24: =COUNTIF('Healthcare Insurance'!F2:F47,"Smoker") -> 11 | D24: =COUNTIF('Healthcare Insurance'!F2:F47,"Non-Smoker") -> 35
B26: Which location has the highest number of customers?
B29: What is the average insurance price by gender?
C30: Male | D30: Female
C31: =AVERAGEIF('Healthcare Insurance'!C2:C47,"Male",'Healthcare Insurance'!H2:H47) -> 22412.609 | D31: =AVERAGEIF('Healthcare Insurance'!C2:C47,"Female",'Healthcare Insurance'!H2:H47) -> 14076.087
B33: Compare average insurance price for smokers vs non-smokers.
C34: Smokers | D34: Non-Smokers
C35: =AVERAGEIF('Healthcare Insurance'!F2:F47,"Smoker",'Healthcare Insurance'!H2:H47) -> 24429.091 | D35: =AVERAGEIF('Healthcare Insurance'!F2:F47,"Non-Smoker",'Healthcare Insurance'!H2:H47) -> 16300.571
B37: What is the average insurance price by location?
C38: Row Labels | D38: Average of Insurance Price (USD)
C39: Albuquerque | D39: 22400
C40: Arlington | D40: 15640
C41: Atlanta | D41: 9900
C42: Austin | D42: 18920
C43: Baltimore | D43: 21830
C44: Boston | D44: 12210
C45: Charlotte | D45: 20100
C46: Chicago | D46: 21080
C47: Columbus | D47: 17550
C48: Dallas | D48: 19720
C49: Denver | D49: 17280
C50: Detroit | D50: 12210
... C85: Grand Total | D85: 18244.348
B87: Does insurance price increase with age?
...
